Workbook

Sheet Branch Summary 
A3: SALES EXECUTIVES | B3: DATE | C3: MEET & GREET | D3: QUALIFICATION | E3: VEHICLE PRESENTATION | F3: VEHICLE DEMONSTRATION | G3: NEGOTIATION & CLOSING | H3: DELIVERY & FOLLOW UP | I3: BYD SPECIFIC REQUIREMENTS | J3: TOTAL AVERAGE SCORE
A4: ='Participant 1'!B7 -> Participant 1 | B4: ='Participant 1'!B3 -> 0 | C4: ='Participant 1'!G14 -> 0 | D4: ='Participant 1'!G15 -> 0 | E4: ='Participant 1'!G16 -> 0 | F4: ='Participant 1'!G17 -> 0 | G4: ='Participant 1'!G18 -> 0 | H4: ='Participant 1'!G19 -> 0 | I4: ='Participant 1'!G20 -> 0 | J4: =AVERAGE(C4:I4) -> 0
A5: ='Participant 2'!$B$7 -> Participant 2 | B5: ='Participant 2'!B3 -> 0 | C5: ='Participant 2'!G14 -> 0 | D5: ='Participant 2'!G15 -> 0 | E5: ='Participant 2'!G16 -> 0 | F5: ='Participant 2'!G17 -> 0 | G5: ='Participant 2'!G18 -> 0 | H5: ='Participant 2'!G19 -> 0 | I5: ='Participant 2'!G20 -> 0 | J5: =AVERAGE(C5:I5) -> 0
A6: ='Participant 3'!$B$7 -> Participant 3 | B6: ='Participant 3'!B4 -> 0 | C6: ='Participant 3'!G14 -> 0 | D6: ='Participant 3'!G15 -> 0 | E6: ='Participant 3'!G16 -> 0 | F6: ='Participant 3'!G17 -> 0 | G6: ='Participant 3'!G18 -> 0 | H6: ='Participant 3'!G19 -> 0 | I6: ='Participant 3'!G20 -> 0 | J6: =AVERAGE(C6:I6) -> 0
A7: ='Participant 4'!$B$7 -> Participant 4 | B7: ='Participant 4'!B5 -> 0 | C7: ='Participant 4'!G14 -> 0 | D7: ='Participant 4'!G15 -> 0 | E7: ='Participant 4'!G16 -> 0 | F7: ='Participant 4'!G17 -> 0 | G7: ='Participant 4'!G18 -> 0 | H7: ='Participant 4'!G19 -> 0 | I7: ='Participant 4'!G20 -> 0 | J7: =AVERAGE(C7:I7) -> 0
A8: ='Participant 5'!$B$7 -> Participant 5 | B8: ='Participant 5'!B6 -> 0 | C8: ='Participant 5'!G14 -> 0 | D8: ='Participant 5'!G15 -> 0 | E8: ='Participant 5'!G16 -> 0 | F8: ='Participant 5'!G17 -> 0 | G8: ='Participant 5'!G18 -> 0 | H8: ='Participant 5'!G19 -> 0 | I8: ='Participant 5'!G20 -> 0 | J8: =AVERAGE(C8:I8) -> 0
A9: ='Patricipant 6'!B7 -> Participant 6 | B9: ='Patricipant 6'!B3 -> 0 | C9: ='Patricipant 6'!G14 -> 0 | D9: ='Patricipant 6'!G15 -> 0 | E9: ='Patricipant 6'!G16 -> 0 | F9: ='Patricipant 6'!G17 -> 0 | G9: ='Patricipant 6'!G18 -> 0 | H9: ='Patricipant 6'!G19 -> 0 | I9: ='Patricipant 6'!G20 -> 0 | J9: =AVERAGE(C9:I9) -> 0
A10: ='Participant 7'!$B$7 -> Participant 7 | B10: ='Participant 7'!B8 -> 0 | C10: ='Participant 7'!G14 -> 0 | D10: ='Participant 7'!G15 -> 0 | E10: ='Participant 7'!G16 -> 0 | F10: ='Participant 7'!G17 -> 0 | G10: ='Participant 7'!G18 -> 0 | H10: ='Participant 7'!G19 -> 0 | I10: ='Participant 7'!G20 -> 0 | J10: =AVERAGE(C10:I10) -> 0
A11: ='Participant 8'!$B$7 -> Participant 8 | B11: ='Participant 8'!B9 -> 0 | C11: ='Participant 8'!G14 -> 0 | D11: ='Participant 8'!G15 -> 0 | E11: ='Participant 8'!G16 -> 0 | F11: ='Participant 8'!G17 -> 0 | G11: ='Participant 8'!G18 -> 0 | H11: ='Participant 8'!G19 -> 0 | I11: ='Participant 8'!G20 -> 0 | J11: =AVERAGE(C11:I11) -> 0
A12: ='Participant 9'!$B$7 -> Participant 9 | B12: ='Participant 9'!B10 -> 0 | C12: ='Participant 9'!G14 -> 0 | D12: ='Participant 10'!G15 -> 0 | E12: ='Participant 9'!G16 -> 0 | F12: ='Participant 9'!G17 -> 0 | G12: ='Participant 9'!G18 -> 0 | H12: ='Participant 9'!G19 -> 0 | I12: ='Participant 9'!G20 -> 0 | J12: =AVERAGE(C12:I12) -> 0
A13: ='Participant 10'!$B$7 -> Participant 10 | B13: ='Participant 10'!B11 -> 0 | C13: ='Participant 10'!G14 -> 0 | D13: ='Participant 9'!G15 -> 0 | E13: ='Participant 10'!G16 -> 0 | F13: ='Participant 10'!G17 -> 0 | G13: ='Participant 10'!G18 -> 0 | H13: ='Participant 10'!G19 -> 0 | I13: ='Participant 10'!G20 -> 0 | J13: =AVERAGE(C13:I13) -> 0
C14: MEET & GREET | D14: QUALIFICATION | E14: VEHICLE PRESENTATION | F14: VEHICLE DEMONSTRATION | G14: NEGOTIATION & CLOSING | H14: DELIVERY & FOLLOW UP | I14: BYD SPECIFIC REQUIREMENTS | J14: TOTAL AVERAGE SCORE
A15: Average Scores (Completed) | C15: =AVERAGE(C4:C12) -> 0 | D15: =AVERAGE(D4:D12) -> 0 | E15: =AVERAGE(E4:E12) -> 0 | F15: =AVERAGE(F4:F12) -> 0 | G15: =AVERAGE(G4:G12) -> 0 | H15: =AVERAGE(H4:H12) -> 0 | I15: =AVERAGE(I4:I12) -> 0 | J15: =AVERAGE(J4:J12) -> 0
A18: GROs | B18: DATE | C18: MEET & GREET
A19: ='GRO 1'!B7 -> GRO 1 | C19: ='GRO 1'!G13 -> 0
A20: ='GRO 2'!B7 -> GRO 2 | C20: ='GRO 2'!G13 -> 0
A21: ='GRO 3'!B7 -> GRO 3 | C21: ='GRO 3'!G13 -> 0
A22: Average Score | C22: =AVERAGE(C19:C21) -> 0
A25: HANDOVER SPECIALIST | B25: DATE | C25: MEET & GREET | D25: DELIVERY & FOLLOW UP | E25: BRAND SPECIFIC REQUIREMENTS | F25: TOTAL SCORE
A26: ='Handover Specialist 1'!B7 -> HOS 1 | C26: ='Handover Specialist 1'!G13 -> 0 | D26: ='Handover Specialist 1'!G14 -> 0 | E26: ='Handover Specialist 1'!G15 -> 0 | F26: =AVERAGE(C26:E26) -> 0
A27: ='Handover Specialist 2'!B7 -> HOS 2 | C27: ='Handover Specialist 2'!G13 -> 0 | D27: ='Handover Specialist 2'!G14 -> 0 | E27: ='Handover Specialist 2'!G15 -> 0 | F27: =AVERAGE(C27:E27) -> 0
A28: ='Handover Specialist 3'!B7 -> HOS 3 | C28: ='Handover Specialist 3'!G13 -> 0 | D28: ='Handover Specialist 3'!G14 -> 0 | E28: ='Handover Specialist 3'!G15 -> 0 | F28: =AVERAGE(C28:E28) -> 0
A30: Average Score | C30: =AVERAGE(C26:C28) -> 0 | D30: =AVERAGE(D26:D28) -> 0 | E30: =AVERAGE(E26:E28) -> 0 | F30: =AVERAGE(F26:F28) -> 0
B32: Score | C32: Pass | D32: Fail | E32: Max
A33: MEET & GREET | B33: =C15 -> 0 | C33: 0.8 | D33: 0.6 | E33: 1
A34: QUALIFICATION | B34: =D15 -> 0 | C34: 0.8 | D34: 0.6 | E34: 1
A35: VEHICLE PRESENTATION | B35: =E15 -> 0 | C35: 0.8 | D35: 0.6 | E35: 1
A36: VEHICLE DEMONSTRATION | B36: =F15 -> 0 | C36: 0.8 | D36: 0.6 | E36: 1
A37: NEGOTIATION & CLOSING | B37: =G15 -> 0 | C37: 0.8 | D37: 0.6 | E37: 1
A38: DELIVERY & FOLLOW UP | B38: =H15 -> 0 | C38: 0.8 | D38: 0.6 | E38: 1
A39: BRAND SPECIFIC REQUIREMENTS | B39: =I15 -> 0 | C39: 0.8 | D39: 0.6 | E39: 1
A40: Total Average Score | B40: =J15 -> 0

Sheet Participant 1
A1: SKILLS EVALUATION ASSESSMENT
A3: Date
A4: Brand
A5: Dealership
A6: Position
A7: Name | B7: Participant 1
A8: Start Date
A9: Assessor
A10: IQA
B12: TASK 1
B13: MEET & GREET | C13: Y/N | G13: Score | H13: Pass | I13: Fail | J13: Max
B14: Initial Engagement | F14: MEET & GREET | G14: =D45 -> 0 | H14: 0.8 | I14: 0.6 | J14: 1
B15: Approaches customer promptly | C15: No | D15: =IF(C15="Yes",1,0) -> 0 | F15: QUALIFICATION | G15: =SUM(D72) -> 0 | H15: 0.8 | I15: 0.6 | J15: 1
B16: Thank Customer for their interest in the brand | F16: VEHICLE PRESENTATION | G16: =SUM(D99) -> 0 | H16: 0.8 | I16: 0.6 | J16: 1
B17: Displays positive body language | D17: =IF(C17="Yes",1,0) -> 0 | F17: VEHICLE DEMONSTRATION | G17: =SUM(D125) -> 0 | H17: 0.8 | I17: 0.6 | J17: 1
B18: Uses friendly and professional tone | D18: =IF(C18="Yes",1,0) -> 0 | F18: NEGOTIATION & CLOSING | G18: =SUM(D155) -> 0 | H18: 0.8 | I18: 0.6 | J18: 1
B19: Provides a warm and personalized welcome | D19: =IF(C19="Yes",1,0) -> 0 | F19: DELIVERY & FOLLOW UP | G19: =SUM(D182) -> 0 | H19: 0.8 | I19: 0.6 | J19: 1
B20: Introduces self by name and role | D20: =IF(C20="Yes",1,0) -> 0 | F20: BRAND SPECIFIC REQUIREMENTS | G20: =D195 -> 0 | H20: 0.8 | I20: 0.6 | J20: 1
B21: Demonstrates cultural sensitivity | D21: =IF(C21="Yes",1,0) -> 0
B22: Name / Surname | D22: =IF(C22="Yes",1,0) -> 0
B23: Professional Appearance
B24: Follows dress code | D24: =IF(C24="Yes",1,0) -> 0
B25: Maintains neat grooming | D25: =IF(C25="Yes",1,0) -> 0
B26: Wears visible name badge (If not brand required mark as "YES" even if not being worn) | D26: =IF(C26="Yes",1,0) -> 0
B27: Environment Set Up
B28: Showroom is clean and organized | D28: =IF(C28="Yes",1,0) -> 0
B29: Desk is clean, organized and lacks clutter | D29: =IF(C29="Yes",1,0) -> 0
B30: Sales materials are readily available | D30: =IF(C30="Yes",1,0) -> 0
B31: Offers comfort (e.g., water, seating) | D31: =IF(C31="Yes",1,0) -> 0
B32: Communication
B33: Clear voice & tone | D33: =IF(C33="Yes",1,0) -> 0
B34: Enthusiastic and positive energy | D34: =IF(C34="Yes",1,0) -> 0
B35: Confidence | D35: =IF(C35="Yes",1,0) -> 0
B36: Show understanding and empathy | D36: =IF(C36="Yes",1,0) -> 0
B37: Questioning techniques | D37: =IF(C37="Yes",1,0) -> 0
B38: Building rapport and relationship | D38: =IF(C38="Yes",1,0) -> 0
B39: Demonstrate active listening skills | D39: =IF(C39="Yes",1,0) -> 0
B40: Always using the customer name / title | D40: =IF(C40="Yes",1,0) -> 0
B41: Appropriate Body Language | D41: =IF(C41="Yes",1,0) -> 0
B42: Progress through the Sales Process
...

Sheet Participant 2
A1: SKILLS EVALUATION ASSESSMENT
A3: Date
A4: Brand
A5: Dealership
A6: Position
A7: Name | B7: Participant 2
A8: Start Date
A9: Assessor
A10: IQA
B12: TASK 1
B13: MEET & GREET | C13: Y/N | G13: Score | H13: Pass | I13: Fail | J13: Max
B14: Initial Engagement | F14: MEET & GREET | G14: =D45 -> 0 | H14: 0.8 | I14: 0.6 | J14: 1
B15: Approaches customer promptly | D15: =IF(C15="Yes",1,0) -> 0 | F15: QUALIFICATION | G15: =SUM(D72) -> 0 | H15: 0.8 | I15: 0.6 | J15: 1
B16: Thank Customer for their interest in the brand | F16: VEHICLE PRESENTATION | G16: =SUM(D99) -> 0 | H16: 0.8 | I16: 0.6 | J16: 1
B17: Displays positive body language | D17: =IF(C17="Yes",1,0) -> 0 | F17: VEHICLE DEMONSTRATION | G17: =SUM(D125) -> 0 | H17: 0.8 | I17: 0.6 | J17: 1
B18: Uses friendly and professional tone | D18: =IF(C18="Yes",1,0) -> 0 | F18: NEGOTIATION & CLOSING | G18: =SUM(D155) -> 0 | H18: 0.8 | I18: 0.6 | J18: 1
B19: Provides a warm and personalized welcome | D19: =IF(C19="Yes",1,0) -> 0 | F19: DELIVERY & FOLLOW UP | G19: =SUM(D182) -> 0 | H19: 0.8 | I19: 0.6 | J19: 1
B20: Introduces self by name and role | D20: =IF(C20="Yes",1,0) -> 0 | F20: BRAND SPECIFIC REQUIREMENTS | G20: =D195 -> 0 | H20: 0.8 | I20: 0.6 | J20: 1
B21: Demonstrates cultural sensitivity | D21: =IF(C21="Yes",1,0) -> 0
B22: Name / Surname | D22: =IF(C22="Yes",1,0) -> 0
B23: Professional Appearance
B24: Follows dress code | D24: =IF(C24="Yes",1,0) -> 0
B25: Maintains neat grooming | D25: =IF(C25="Yes",1,0) -> 0
B26: Wears visible name badge (If not brand required mark as "YES" even if not being worn) | D26: =IF(C26="Yes",1,0) -> 0
B27: Environment Set Up
B28: Showroom is clean and organized | D28: =IF(C28="Yes",1,0) -> 0
B29: Desk is clean, organized and lacks clutter | D29: =IF(C29="Yes",1,0) -> 0
B30: Sales materials are readily available | D30: =IF(C30="Yes",1,0) -> 0
B31: Offers comfort (e.g., water, seating) | D31: =IF(C31="Yes",1,0) -> 0
B32: Communication
B33: Clear voice & tone | D33: =IF(C33="Yes",1,0) -> 0
B34: Enthusiastic and positive energy | D34: =IF(C34="Yes",1,0) -> 0
B35: Confidence | D35: =IF(C35="Yes",1,0) -> 0
B36: Show understanding and empathy | D36: =IF(C36="Yes",1,0) -> 0
B37: Questioning techniques | D37: =IF(C37="Yes",1,0) -> 0
B38: Building rapport and relationship | D38: =IF(C38="Yes",1,0) -> 0
B39: Demonstrate active listening skills | D39: =IF(C39="Yes",1,0) -> 0
B40: Always using the customer name / title | D40: =IF(C40="Yes",1,0) -> 0
B41: Appropriate Body Language | D41: =IF(C41="Yes",1,0) -> 0
B42: Progress through the Sales Process
...

Sheet Participant 3
A1: SKILLS EVALUATION ASSESSMENT
A3: Date
A4: Brand
A5: Dealership
A6: Position
A7: Name | B7: Participant 3
A8: Start Date
A9: Assessor
A10: IQA
B12: TASK 1
B13: MEET & GREET | C13: Y/N | G13: Score | H13: Pass | I13: Fail | J13: Max
B14: Initial Engagement | F14: MEET & GREET | G14: =D45 -> 0 | H14: 0.8 | I14: 0.5 | J14: 1
B15: Approaches customer promptly | D15: =IF(C15="Yes",1,0) -> 0 | F15: QUALIFICATION | G15: =SUM(D72) -> 0 | H15: 0.8 | I15: 0.5 | J15: 1
B16: Thank Customer for their interest in the brand | F16: VEHICLE PRESENTATION | G16: =SUM(D99) -> 0 | H16: 0.8 | I16: 0.5 | J16: 1
B17: Displays positive body language | D17: =IF(C17="Yes",1,0) -> 0 | F17: VEHICLE DEMONSTRATION | G17: =SUM(D125) -> 0 | H17: 0.8 | I17: 0.5 | J17: 1
B18: Uses friendly and professional tone | D18: =IF(C18="Yes",1,0) -> 0 | F18: NEGOTIATION & CLOSING | G18: =SUM(D155) -> 0 | H18: 0.8 | I18: 0.5 | J18: 1
B19: Provides a warm and personalized welcome | D19: =IF(C19="Yes",1,0) -> 0 | F19: DELIVERY & FOLLOW UP | G19: =SUM(D182) -> 0 | H19: 0.8 | I19: 0.5 | J19: 1
B20: Introduces self by name and role | D20: =IF(C20="Yes",1,0) -> 0 | F20: BRAND SPECIFIC REQUIREMENTS | G20: =D195 -> 0 | H20: 0.8 | I20: 0.5 | J20: 1
B21: Demonstrates cultural sensitivity | D21: =IF(C21="Yes",1,0) -> 0
B22: Name / Surname | D22: =IF(C22="Yes",1,0) -> 0
B23: Professional Appearance
B24: Follows dress code | D24: =IF(C24="Yes",1,0) -> 0
B25: Maintains neat grooming | D25: =IF(C25="Yes",1,0) -> 0
B26: Wears visible name badge (If not brand required mark as "YES" even if not being worn) | D26: =IF(C26="Yes",1,0) -> 0
B27: Environment Set Up
B28: Showroom is clean and organized | D28: =IF(C28="Yes",1,0) -> 0
B29: Desk is clean, organized and lacks clutter | D29: =IF(C29="Yes",1,0) -> 0
B30: Sales materials are readily available | D30: =IF(C30="Yes",1,0) -> 0
B31: Offers comfort (e.g., water, seating) | D31: =IF(C31="Yes",1,0) -> 0
B32: Communication
B33: Clear voice & tone | D33: =IF(C33="Yes",1,0) -> 0
B34: Enthusiastic and positive energy | D34: =IF(C34="Yes",1,0) -> 0
B35: Confidence | D35: =IF(C35="Yes",1,0) -> 0
B36: Show understanding and empathy | D36: =IF(C36="Yes",1,0) -> 0
B37: Questioning techniques | D37: =IF(C37="Yes",1,0) -> 0
B38: Building rapport and relationship | D38: =IF(C38="Yes",1,0) -> 0
B39: Demonstrate active listening skills | D39: =IF(C39="Yes",1,0) -> 0
B40: Always using the customer name / title | D40: =IF(C40="Yes",1,0) -> 0
B41: Appropriate Body Language | D41: =IF(C41="Yes",1,0) -> 0
B42: Progress through the Sales Process
...

Sheet Participant 4
A1: SKILLS EVALUATION ASSESSMENT
A3: Date
A4: Brand
A5: Dealership
A6: Position
A7: Name | B7: Participant 4
A8: Start Date
A9: Assessor
A10: IQA
B12: TASK 1
B13: MEET & GREET | C13: Y/N | G13: Score | H13: Pass | I13: Fail | J13: Max
B14: Initial Engagement | F14: MEET & GREET | G14: =D45 -> 0 | H14: 0.8 | I14: 0.6 | J14: 1
B15: Approaches customer promptly | D15: =IF(C15="Yes",1,0) -> 0 | F15: QUALIFICATION | G15: =SUM(D72) -> 0 | H15: 0.8 | I15: 0.6 | J15: 1
B16: Thank Customer for their interest in the brand | F16: VEHICLE PRESENTATION | G16: =SUM(D99) -> 0 | H16: 0.8 | I16: 0.6 | J16: 1
B17: Displays positive body language | D17: =IF(C17="Yes",1,0) -> 0 | F17: VEHICLE DEMONSTRATION | G17: =SUM(D125) -> 0 | H17: 0.8 | I17: 0.6 | J17: 1
B18: Uses friendly and professional tone | D18: =IF(C18="Yes",1,0) -> 0 | F18: NEGOTIATION & CLOSING | G18: =SUM(D155) -> 0 | H18: 0.8 | I18: 0.6 | J18: 1
B19: Provides a warm and personalized welcome | D19: =IF(C19="Yes",1,0) -> 0 | F19: DELIVERY & FOLLOW UP | G19: =SUM(D182) -> 0 | H19: 0.8 | I19: 0.6 | J19: 1
B20: Introduces self by name and role | D20: =IF(C20="Yes",1,0) -> 0 | F20: BRAND SPECIFIC REQUIREMENTS | G20: =D195 -> 0 | H20: 0.8 | I20: 0.6 | J20: 1
B21: Demonstrates cultural sensitivity | D21: =IF(C21="Yes",1,0) -> 0
B22: Name / Surname | D22: =IF(C22="Yes",1,0) -> 0
B23: Professional Appearance
B24: Follows dress code | D24: =IF(C24="Yes",1,0) -> 0
B25: Maintains neat grooming | D25: =IF(C25="Yes",1,0) -> 0
B26: Wears visible name badge (If not brand required mark as "YES" even if not being worn) | D26: =IF(C26="Yes",1,0) -> 0
B27: Environment Set Up
B28: Showroom is clean and organized | D28: =IF(C28="Yes",1,0) -> 0
B29: Desk is clean, organized and lacks clutter | D29: =IF(C29="Yes",1,0) -> 0
B30: Sales materials are readily available | D30: =IF(C30="Yes",1,0) -> 0
B31: Offers comfort (e.g., water, seating) | D31: =IF(C31="Yes",1,0) -> 0
B32: Communication
B33: Clear voice & tone | D33: =IF(C33="Yes",1,0) -> 0
B34: Enthusiastic and positive energy | D34: =IF(C34="Yes",1,0) -> 0
B35: Confidence | D35: =IF(C35="Yes",1,0) -> 0
B36: Show understanding and empathy | D36: =IF(C36="Yes",1,0) -> 0
B37: Questioning techniques | D37: =IF(C37="Yes",1,0) -> 0
B38: Building rapport and relationship | D38: =IF(C38="Yes",1,0) -> 0
B39: Demonstrate active listening skills | D39: =IF(C39="Yes",1,0) -> 0
B40: Always using the customer name / title | D40: =IF(C40="Yes",1,0) -> 0
B41: Appropriate Body Language | D41: =IF(C41="Yes",1,0) -> 0
B42: Progress through the Sales Process
...

Sheet Participant 5
A1: SKILLS EVALUATION ASSESSMENT
A3: Date
A4: Brand
A5: Dealership
A6: Position
A7: Name | B7: Participant 5
A8: Start Date
A9: Assessor
A10: IQA
B12: TASK 1
B13: MEET & GREET | C13: Y/N | G13: Score | H13: Pass | I13: Fail | J13: Max
B14: Initial Engagement | F14: MEET & GREET | G14: =D45 -> 0 | H14: 0.8 | I14: 0.6 | J14: 1
B15: Approaches customer promptly | D15: =IF(C15="Yes",1,0) -> 0 | F15: QUALIFICATION | G15: =SUM(D72) -> 0 | H15: 0.8 | I15: 0.6 | J15: 1
B16: Thank Customer for their interest in the brand | F16: VEHICLE PRESENTATION | G16: =SUM(D99) -> 0 | H16: 0.8 | I16: 0.6 | J16: 1
B17: Displays positive body language | D17: =IF(C17="Yes",1,0) -> 0 | F17: VEHICLE DEMONSTRATION | G17: =SUM(D125) -> 0 | H17: 0.8 | I17: 0.6 | J17: 1
B18: Uses friendly and professional tone | D18: =IF(C18="Yes",1,0) -> 0 | F18: NEGOTIATION & CLOSING | G18: =SUM(D155) -> 0 | H18: 0.8 | I18: 0.6 | J18: 1
B19: Provides a warm and personalized welcome | D19: =IF(C19="Yes",1,0) -> 0 | F19: DELIVERY & FOLLOW UP | G19: =SUM(D182) -> 0 | H19: 0.8 | I19: 0.6 | J19: 1
B20: Introduces self by name and role | D20: =IF(C20="Yes",1,0) -> 0 | F20: BRAND SPECIFIC REQUIREMENTS | G20: =D195 -> 0 | H20: 0.8 | I20: 0.6 | J20: 1
B21: Demonstrates cultural sensitivity | D21: =IF(C21="Yes",1,0) -> 0
B22: Name / Surname | D22: =IF(C22="Yes",1,0) -> 0
B23: Professional Appearance
B24: Follows dress code | D24: =IF(C24="Yes",1,0) -> 0
B25: Maintains neat grooming | D25: =IF(C25="Yes",1,0) -> 0
B26: Wears visible name badge (If not brand required mark as "YES" even if not being worn) | D26: =IF(C26="Yes",1,0) -> 0
B27: Environment Set Up
B28: Showroom is clean and organized | D28: =IF(C28="Yes",1,0) -> 0
B29: Desk is clean, organized and lacks clutter | D29: =IF(C29="Yes",1,0) -> 0
B30: Sales materials are readily available | D30: =IF(C30="Yes",1,0) -> 0
B31: Offers comfort (e.g., water, seating) | D31: =IF(C31="Yes",1,0) -> 0
B32: Communication
B33: Clear voice & tone | D33: =IF(C33="Yes",1,0) -> 0
B34: Enthusiastic and positive energy | D34: =IF(C34="Yes",1,0) -> 0
B35: Confidence | D35: =IF(C35="Yes",1,0) -> 0
B36: Show understanding and empathy | D36: =IF(C36="Yes",1,0) -> 0
B37: Questioning techniques | D37: =IF(C37="Yes",1,0) -> 0
B38: Building rapport and relationship | D38: =IF(C38="Yes",1,0) -> 0
B39: Demonstrate active listening skills | D39: =IF(C39="Yes",1,0) -> 0
B40: Always using the customer name / title | D40: =IF(C40="Yes",1,0) -> 0
B41: Appropriate Body Language | D41: =IF(C41="Yes",1,0) -> 0
B42: Progress through the Sales Process
...

Sheet Patricipant 6
A1: SKILLS EVALUATION ASSESSMENT
A3: Date
A4: Brand
A5: Dealership
A6: Position
A7: Name | B7: Participant 6
A8: Start Date
A9: Assessor
A10: IQA
B12: TASK 1
B13: MEET & GREET | C13: Y/N | G13: Score | H13: Pass | I13: Fail | J13: Max
B14: Initial Engagement | F14: MEET & GREET | G14: =D45 -> 0 | H14: 0.8 | I14: 0.6 | J14: 1
B15: Approaches customer promptly | D15: =IF(C15="Yes",1,0) -> 0 | F15: QUALIFICATION | G15: =SUM(D72) -> 0 | H15: 0.8 | I15: 0.6 | J15: 1
B16: Thank Customer for their interest in the brand | F16: VEHICLE PRESENTATION | G16: =SUM(D99) -> 0 | H16: 0.8 | I16: 0.6 | J16: 1
B17: Displays positive body language | D17: =IF(C17="Yes",1,0) -> 0 | F17: VEHICLE DEMONSTRATION | G17: =SUM(D125) -> 0 | H17: 0.8 | I17: 0.6 | J17: 1
B18: Uses friendly and professional tone | D18: =IF(C18="Yes",1,0) -> 0 | F18: NEGOTIATION & CLOSING | G18: =SUM(D155) -> 0 | H18: 0.8 | I18: 0.6 | J18: 1
B19: Provides a warm and personalized welcome | D19: =IF(C19="Yes",1,0) -> 0 | F19: DELIVERY & FOLLOW UP | G19: =SUM(D182) -> 0 | H19: 0.8 | I19: 0.6 | J19: 1
B20: Introduces self by name and role | D20: =IF(C20="Yes",1,0) -> 0 | F20: BRAND SPECIFIC REQUIREMENTS | G20: =D195 -> 0 | H20: 0.8 | I20: 0.6 | J20: 1
B21: Demonstrates cultural sensitivity | D21: =IF(C21="Yes",1,0) -> 0
B22: Name / Surname | D22: =IF(C22="Yes",1,0) -> 0
B23: Professional Appearance
B24: Follows dress code | D24: =IF(C24="Yes",1,0) -> 0
B25: Maintains neat grooming | D25: =IF(C25="Yes",1,0) -> 0
B26: Wears visible name badge (If not brand required mark as "YES" even if not being worn) | D26: =IF(C26="Yes",1,0) -> 0
B27: Environment Set Up
B28: Showroom is clean and organized | D28: =IF(C28="Yes",1,0) -> 0
B29: Desk is clean, organized and lacks clutter | D29: =IF(C29="Yes",1,0) -> 0
B30: Sales materials are readily available | D30: =IF(C30="Yes",1,0) -> 0
B31: Offers comfort (e.g., water, seating) | D31: =IF(C31="Yes",1,0) -> 0
B32: Communication
B33: Clear voice & tone | D33: =IF(C33="Yes",1,0) -> 0
B34: Enthusiastic and positive energy | D34: =IF(C34="Yes",1,0) -> 0
B35: Confidence | D35: =IF(C35="Yes",1,0) -> 0
B36: Show understanding and empathy | D36: =IF(C36="Yes",1,0) -> 0
B37: Questioning techniques | D37: =IF(C37="Yes",1,0) -> 0
B38: Building rapport and relationship | D38: =IF(C38="Yes",1,0) -> 0
B39: Demonstrate active listening skills | D39: =IF(C39="Yes",1,0) -> 0
B40: Always using the customer name / title | D40: =IF(C40="Yes",1,0) -> 0
B41: Appropriate Body Language | D41: =IF(C41="Yes",1,0) -> 0
B42: Progress through the Sales Process
...

Sheet Participant 7
A1: SKILLS EVALUATION ASSESSMENT
A3: Date
A4: Brand
A5: Dealership
A6: Position
A7: Name | B7: Participant 7
A8: Start Date
A9: Assessor
A10: IQA
B12: TASK 1
B13: MEET & GREET | C13: Y/N | G13: Score | H13: Pass | I13: Fail | J13: Max
B14: Initial Engagement | F14: MEET & GREET | G14: =D45 -> 0 | H14: 0.8 | I14: 0.6 | J14: 1
B15: Approaches customer promptly | D15: =IF(C15="Yes",1,0) -> 0 | F15: QUALIFICATION | G15: =SUM(D72) -> 0 | H15: 0.8 | I15: 0.6 | J15: 1
B16: Thank Customer for their interest in the brand | F16: VEHICLE PRESENTATION | G16: =SUM(D99) -> 0 | H16: 0.8 | I16: 0.6 | J16: 1
B17: Displays positive body language | D17: =IF(C17="Yes",1,0) -> 0 | F17: VEHICLE DEMONSTRATION | G17: =SUM(D125) -> 0 | H17: 0.8 | I17: 0.6 | J17: 1
B18: Uses friendly and professional tone | D18: =IF(C18="Yes",1,0) -> 0 | F18: NEGOTIATION & CLOSING | G18: =SUM(D155) -> 0 | H18: 0.8 | I18: 0.6 | J18: 1
B19: Provides a warm and personalized welcome | D19: =IF(C19="Yes",1,0) -> 0 | F19: DELIVERY & FOLLOW UP | G19: =SUM(D182) -> 0 | H19: 0.8 | I19: 0.6 | J19: 1
B20: Introduces self by name and role | D20: =IF(C20="Yes",1,0) -> 0 | F20: BRAND SPECIFIC REQUIREMENTS | G20: =D195 -> 0 | H20: 0.8 | I20: 0.6 | J20: 1
B21: Demonstrates cultural sensitivity | D21: =IF(C21="Yes",1,0) -> 0
B22: Name / Surname | D22: =IF(C22="Yes",1,0) -> 0
B23: Professional Appearance
B24: Follows dress code | D24: =IF(C24="Yes",1,0) -> 0
B25: Maintains neat grooming | D25: =IF(C25="Yes",1,0) -> 0
B26: Wears visible name badge (If not brand required mark as "YES" even if not being worn) | D26: =IF(C26="Yes",1,0) -> 0
B27: Environment Set Up
B28: Showroom is clean and organized | D28: =IF(C28="Yes",1,0) -> 0
B29: Desk is clean, organized and lacks clutter | D29: =IF(C29="Yes",1,0) -> 0
B30: Sales materials are readily available | D30: =IF(C30="Yes",1,0) -> 0
B31: Offers comfort (e.g., water, seating) | D31: =IF(C31="Yes",1,0) -> 0
B32: Communication
B33: Clear voice & tone | D33: =IF(C33="Yes",1,0) -> 0
B34: Enthusiastic and positive energy | D34: =IF(C34="Yes",1,0) -> 0
B35: Confidence | D35: =IF(C35="Yes",1,0) -> 0
B36: Show understanding and empathy | D36: =IF(C36="Yes",1,0) -> 0
B37: Questioning techniques | D37: =IF(C37="Yes",1,0) -> 0
B38: Building rapport and relationship | D38: =IF(C38="Yes",1,0) -> 0
B39: Demonstrate active listening skills | D39: =IF(C39="Yes",1,0) -> 0
B40: Always using the customer name / title | D40: =IF(C40="Yes",1,0) -> 0
B41: Appropriate Body Language | D41: =IF(C41="Yes",1,0) -> 0
B42: Progress through the Sales Process
...

Sheet Participant 8
A1: SKILLS EVALUATION ASSESSMENT
A3: Date
A4: Brand
A5: Dealership
A6: Position
A7: Name | B7: Participant 8
A8: Start Date
A9: Assessor
A10: IQA
B12: TASK 1
B13: MEET & GREET | C13: Y/N | G13: Score | H13: Pass | I13: Fail | J13: Max
B14: Initial Engagement | F14: MEET & GREET | G14: =D45 -> 0 | H14: 0.8 | I14: 0.6 | J14: 1
B15: Approaches customer promptly | D15: =IF(C15="Yes",1,0) -> 0 | F15: QUALIFICATION | G15: =SUM(D72) -> 0 | H15: 0.8 | I15: 0.6 | J15: 1
B16: Thank Customer for their interest in the brand | F16: VEHICLE PRESENTATION | G16: =SUM(D99) -> 0 | H16: 0.8 | I16: 0.6 | J16: 1
B17: Displays positive body language | D17: =IF(C17="Yes",1,0) -> 0 | F17: VEHICLE DEMONSTRATION | G17: =SUM(D125) -> 0 | H17: 0.8 | I17: 0.6 | J17: 1
B18: Uses friendly and professional tone | D18: =IF(C18="Yes",1,0) -> 0 | F18: NEGOTIATION & CLOSING | G18: =SUM(D155) -> 0 | H18: 0.8 | I18: 0.6 | J18: 1
B19: Provides a warm and personalized welcome | D19: =IF(C19="Yes",1,0) -> 0 | F19: DELIVERY & FOLLOW UP | G19: =SUM(D182) -> 0 | H19: 0.8 | I19: 0.6 | J19: 1
B20: Introduces self by name and role | D20: =IF(C20="Yes",1,0) -> 0 | F20: BRAND SPECIFIC REQUIREMENTS | G20: =D195 -> 0 | H20: 0.8 | I20: 0.6 | J20: 1
B21: Demonstrates cultural sensitivity | D21: =IF(C21="Yes",1,0) -> 0
B22: Name / Surname | D22: =IF(C22="Yes",1,0) -> 0
B23: Professional Appearance
B24: Follows dress code | D24: =IF(C24="Yes",1,0) -> 0
B25: Maintains neat grooming | D25: =IF(C25="Yes",1,0) -> 0
B26: Wears visible name badge (If not brand required mark as "YES" even if not being worn) | D26: =IF(C26="Yes",1,0) -> 0
B27: Environment Set Up
B28: Showroom is clean and organized | D28: =IF(C28="Yes",1,0) -> 0
B29: Desk is clean, organized and lacks clutter | D29: =IF(C29="Yes",1,0) -> 0
B30: Sales materials are readily available | D30: =IF(C30="Yes",1,0) -> 0
B31: Offers comfort (e.g., water, seating) | D31: =IF(C31="Yes",1,0) -> 0
B32: Communication
B33: Clear voice & tone | D33: =IF(C33="Yes",1,0) -> 0
B34: Enthusiastic and positive energy | D34: =IF(C34="Yes",1,0) -> 0
B35: Confidence | D35: =IF(C35="Yes",1,0) -> 0
B36: Show understanding and empathy | D36: =IF(C36="Yes",1,0) -> 0
B37: Questioning techniques | D37: =IF(C37="Yes",1,0) -> 0
B38: Building rapport and relationship | D38: =IF(C38="Yes",1,0) -> 0
B39: Demonstrate active listening skills | D39: =IF(C39="Yes",1,0) -> 0
B40: Always using the customer name / title | D40: =IF(C40="Yes",1,0) -> 0
B41: Appropriate Body Language | D41: =IF(C41="Yes",1,0) -> 0
B42: Progress through the Sales Process
...

Sheet Participant 9
A1: SKILLS EVALUATION ASSESSMENT
A3: Date
A4: Brand
A5: Dealership
A6: Position
A7: Name | B7: Participant 9
A8: Start Date
A9: Assessor
A10: IQA
B12: TASK 1
B13: MEET & GREET | C13: Y/N | G13: Score | H13: Pass | I13: Fail | J13: Max
B14: Initial Engagement | F14: MEET & GREET | G14: =D45 -> 0 | H14: 0.8 | I14: 0.6 | J14: 1
B15: Approaches customer promptly | D15: =IF(C15="Yes",1,0) -> 0 | F15: QUALIFICATION | G15: =SUM(D72) -> 0 | H15: 0.8 | I15: 0.6 | J15: 1
B16: Thank Customer for their interest in the brand | F16: VEHICLE PRESENTATION | G16: =SUM(D99) -> 0 | H16: 0.8 | I16: 0.6 | J16: 1
B17: Displays positive body language | D17: =IF(C17="Yes",1,0) -> 0 | F17: VEHICLE DEMONSTRATION | G17: =SUM(D125) -> 0 | H17: 0.8 | I17: 0.6 | J17: 1
B18: Uses friendly and professional tone | D18: =IF(C18="Yes",1,0) -> 0 | F18: NEGOTIATION & CLOSING | G18: =SUM(D155) -> 0 | H18: 0.8 | I18: 0.6 | J18: 1
B19: Provides a warm and personalized welcome | D19: =IF(C19="Yes",1,0) -> 0 | F19: DELIVERY & FOLLOW UP | G19: =SUM(D182) -> 0 | H19: 0.8 | I19: 0.6 | J19: 1
B20: Introduces self by name and role | D20: =IF(C20="Yes",1,0) -> 0 | F20: BRAND SPECIFIC REQUIREMENTS | G20: =D195 -> 0 | H20: 0.8 | I20: 0.6 | J20: 1
B21: Demonstrates cultural sensitivity | D21: =IF(C21="Yes",1,0) -> 0
B22: Name / Surname | D22: =IF(C22="Yes",1,0) -> 0
B23: Professional Appearance
B24: Follows dress code | D24: =IF(C24="Yes",1,0) -> 0
B25: Maintains neat grooming | D25: =IF(C25="Yes",1,0) -> 0
B26: Wears visible name badge (If not brand required mark as "YES" even if not being worn) | D26: =IF(C26="Yes",1,0) -> 0
B27: Environment Set Up
B28: Showroom is clean and organized | D28: =IF(C28="Yes",1,0) -> 0
B29: Desk is clean, organized and lacks clutter | D29: =IF(C29="Yes",1,0) -> 0
B30: Sales materials are readily available | D30: =IF(C30="Yes",1,0) -> 0
B31: Offers comfort (e.g., water, seating) | D31: =IF(C31="Yes",1,0) -> 0
B32: Communication
B33: Clear voice & tone | D33: =IF(C33="Yes",1,0) -> 0
B34: Enthusiastic and positive energy | D34: =IF(C34="Yes",1,0) -> 0
B35: Confidence | D35: =IF(C35="Yes",1,0) -> 0
B36: Show understanding and empathy | D36: =IF(C36="Yes",1,0) -> 0
B37: Questioning techniques | D37: =IF(C37="Yes",1,0) -> 0
B38: Building rapport and relationship | D38: =IF(C38="Yes",1,0) -> 0
B39: Demonstrate active listening skills | D39: =IF(C39="Yes",1,0) -> 0
B40: Always using the customer name / title | D40: =IF(C40="Yes",1,0) -> 0
B41: Appropriate Body Language | D41: =IF(C41="Yes",1,0) -> 0
B42: Progress through the Sales Process
...

Sheet Participant 10
A1: SKILLS EVALUATION ASSESSMENT
A3: Date
A4: Brand
A5: Dealership
A6: Position
A7: Name | B7: Participant 10
A8: Start Date
A9: Assessor
A10: IQA
B12: TASK 1
B13: MEET & GREET | C13: Y/N | G13: Score | H13: Pass | I13: Fail | J13: Max
B14: Initial Engagement | F14: MEET & GREET | G14: =D45 -> 0 | H14: 0.8 | I14: 0.6 | J14: 1
B15: Approaches customer promptly | D15: =IF(C15="Yes",1,0) -> 0 | F15: QUALIFICATION | G15: =SUM(D72) -> 0 | H15: 0.8 | I15: 0.6 | J15: 1
B16: Thank Customer for their interest in the brand | F16: VEHICLE PRESENTATION | G16: =SUM(D99) -> 0 | H16: 0.8 | I16: 0.6 | J16: 1
B17: Displays positive body language | D17: =IF(C17="Yes",1,0) -> 0 | F17: VEHICLE DEMONSTRATION | G17: =SUM(D125) -> 0 | H17: 0.8 | I17: 0.6 | J17: 1
B18: Uses friendly and professional tone | D18: =IF(C18="Yes",1,0) -> 0 | F18: NEGOTIATION & CLOSING | G18: =SUM(D155) -> 0 | H18: 0.8 | I18: 0.6 | J18: 1
B19: Provides a warm and personalized welcome | D19: =IF(C19="Yes",1,0) -> 0 | F19: DELIVERY & FOLLOW UP | G19: =SUM(D182) -> 0 | H19: 0.8 | I19: 0.6 | J19: 1
B20: Introduces self by name and role | D20: =IF(C20="Yes",1,0) -> 0 | F20: BRAND SPECIFIC REQUIREMENTS | G20: =D195 -> 0 | H20: 0.8 | I20: 0.6 | J20: 1
B21: Demonstrates cultural sensitivity | D21: =IF(C21="Yes",1,0) -> 0
B22: Name / Surname | D22: =IF(C22="Yes",1,0) -> 0
B23: Professional Appearance
B24: Follows dress code | D24: =IF(C24="Yes",1,0) -> 0
B25: Maintains neat grooming | D25: =IF(C25="Yes",1,0) -> 0
B26: Wears visible name badge (If not brand required mark as "YES" even if not being worn) | D26: =IF(C26="Yes",1,0) -> 0
B27: Environment Set Up
B28: Showroom is clean and organized | D28: =IF(C28="Yes",1,0) -> 0
B29: Desk is clean, organized and lacks clutter | D29: =IF(C29="Yes",1,0) -> 0
B30: Sales materials are readily available | D30: =IF(C30="Yes",1,0) -> 0
B31: Offers comfort (e.g., water, seating) | D31: =IF(C31="Yes",1,0) -> 0
B32: Communication
B33: Clear voice & tone | D33: =IF(C33="Yes",1,0) -> 0
B34: Enthusiastic and positive energy | D34: =IF(C34="Yes",1,0) -> 0
B35: Confidence | D35: =IF(C35="Yes",1,0) -> 0
B36: Show understanding and empathy | D36: =IF(C36="Yes",1,0) -> 0
B37: Questioning techniques | D37: =IF(C37="Yes",1,0) -> 0
B38: Building rapport and relationship | D38: =IF(C38="Yes",1,0) -> 0
B39: Demonstrate active listening skills | D39: =IF(C39="Yes",1,0) -> 0
B40: Always using the customer name / title | D40: =IF(C40="Yes",1,0) -> 0
B41: Appropriate Body Language | D41: =IF(C41="Yes",1,0) -> 0
B42: Progress through the Sales Process
...

Sheet GRO 1
A1: SKILLS EVALUATION ASSESSMENT
A3: Date
A4: Brand
A5: Dealership
A6: Position
A7: Name | B7: GRO 1
A8: Start Date
A9: Assessor
B11: TASK 1
B12: MEET & GREET | C12: Y/N | G12: Score | H12: Pass | I12: Fail | J12: Max
B13: Initial Engagement | F13: MEET & GREET | G13: =D43 -> 0 | H13: 0.8 | I13: 0.6 | J13: 1
B14: Approaches customer promptly | D14: =IF(C14="Yes",1,0) -> 0
B15: Thank Customer for their interest in the brand | D15: =IF(C15="Yes",1,0) -> 0
B16: Displays positive body language | D16: =IF(C16="Yes",1,0) -> 0
B17: Uses friendly and professional tone | D17: =IF(C17="Yes",1,0) -> 0
B18: Provides a warm and personalized welcome | D18: =IF(C18="Yes",1,0) -> 0
B19: Introduces self by name and role | D19: =IF(C19="Yes",1,0) -> 0
B20: Demonstrates cultural sensitivity | D20: =IF(C20="Yes",1,0) -> 0
B21: Name / Surname | D21: =IF(C21="Yes",1,0) -> 0
B22: Professional Appearance
B23: Follows dress code | D23: =IF(C23="Yes",1,0) -> 0
B24: Maintains neat grooming | D24: =IF(C24="Yes",1,0) -> 0
B25: Wears visible name badge (If not brand required mark as "YES" even if not being worn) | D25: =IF(C25="Yes",1,0) -> 0
B26: Environment Set Up
B27: Showroom is clean and organized | D27: =IF(C27="Yes",1,0) -> 0
B28: Desk is clean, organized and lacks clutter | D28: =IF(C28="Yes",1,0) -> 0
B29: Sales materials are readily available | D29: =IF(C29="Yes",1,0) -> 0
B30: Offers comfort (e.g., water, seating) | D30: =IF(C30="Yes",1,0) -> 0
B31: Communication
B32: Clear voice & tone | D32: =IF(C32="Yes",1,0) -> 0
B33: Enthusiastic and positive energy | D33: =IF(C33="Yes",1,0) -> 0
B34: Confidence | D34: =IF(C34="Yes",1,0) -> 0
B35: Show understanding and empathy | D35: =IF(C35="Yes",1,0) -> 0
B36: Questioning techniques | D36: =IF(C36="Yes",1,0) -> 0
B37: Building rapport and relationship | D37: =IF(C37="Yes",1,0) -> 0
B38: Demonstrate active listening skills | D38: =IF(C38="Yes",1,0) -> 0
B39: Always using the customer name / title | D39: =IF(C39="Yes",1,0) -> 0
B40: Appropriate Body Language | D40: =IF(C40="Yes",1,0) -> 0
B41: Progress through the Sales Process
B42: Smooth transition to a Sales Executive | D42: =IF(C42="Yes",1,0) -> 0
...

Sheet GRO 2
A1: SKILLS EVALUATION ASSESSMENT
A3: Date
A4: Brand
A5: Dealership
A6: Position
A7: Name | B7: GRO 2
A8: Start Date
A9: Assessor
B11: TASK 1
B12: MEET & GREET | C12: Y/N | G12: Score | H12: Pass | I12: Fail | J12: Max
B13: Initial Engagement | F13: MEET & GREET | G13: =D43 -> 0 | H13: 0.8 | I13: 0.6 | J13: 1
B14: Approaches customer promptly | D14: =IF(C14="Yes",1,0) -> 0
B15: Thank Customer for their interest in the brand | D15: =IF(C15="Yes",1,0) -> 0
B16: Displays positive body language | D16: =IF(C16="Yes",1,0) -> 0
B17: Uses friendly and professional tone | D17: =IF(C17="Yes",1,0) -> 0
B18: Provides a warm and personalized welcome | D18: =IF(C18="Yes",1,0) -> 0
B19: Introduces self by name and role | D19: =IF(C19="Yes",1,0) -> 0
B20: Demonstrates cultural sensitivity | D20: =IF(C20="Yes",1,0) -> 0
B21: Name / Surname | D21: =IF(C21="Yes",1,0) -> 0
B22: Professional Appearance
B23: Follows dress code | D23: =IF(C23="Yes",1,0) -> 0
B24: Maintains neat grooming | D24: =IF(C24="Yes",1,0) -> 0
B25: Wears visible name badge (If not brand required mark as "YES" even if not being worn) | D25: =IF(C25="Yes",1,0) -> 0
B26: Environment Set Up
B27: Showroom is clean and organized | D27: =IF(C27="Yes",1,0) -> 0
B28: Desk is clean, organized and lacks clutter | D28: =IF(C28="Yes",1,0) -> 0
B29: Sales materials are readily available | D29: =IF(C29="Yes",1,0) -> 0
B30: Offers comfort (e.g., water, seating) | D30: =IF(C30="Yes",1,0) -> 0
B31: Communication
B32: Clear voice & tone | D32: =IF(C32="Yes",1,0) -> 0
B33: Enthusiastic and positive energy | D33: =IF(C33="Yes",1,0) -> 0
B34: Confidence | D34: =IF(C34="Yes",1,0) -> 0
B35: Show understanding and empathy | D35: =IF(C35="Yes",1,0) -> 0
B36: Questioning techniques | D36: =IF(C36="Yes",1,0) -> 0
B37: Building rapport and relationship | D37: =IF(C37="Yes",1,0) -> 0
B38: Demonstrate active listening skills | D38: =IF(C38="Yes",1,0) -> 0
B39: Always using the customer name / title | D39: =IF(C39="Yes",1,0) -> 0
B40: Appropriate Body Language | D40: =IF(C40="Yes",1,0) -> 0
B41: Progress through the Sales Process
B42: Smooth transition to a Sales Executive | D42: =IF(C42="Yes",1,0) -> 0
...

Sheet GRO 3
A1: SKILLS EVALUATION ASSESSMENT
A3: Date
A4: Brand
A5: Dealership
A6: Position
A7: Name | B7: GRO 3
A8: Start Date
A9: Assessor
B11: TASK 1
B12: MEET & GREET | C12: Y/N | G12: Score | H12: Pass | I12: Fail | J12: Max
B13: Initial Engagement | F13: MEET & GREET | G13: =D43 -> 0 | H13: 0.8 | I13: 0.6 | J13: 1
B14: Approaches customer promptly | D14: =IF(C14="Yes",1,0) -> 0
B15: Thank Customer for their interest in the brand | D15: =IF(C15="Yes",1,0) -> 0
B16: Displays positive body language | D16: =IF(C16="Yes",1,0) -> 0
B17: Uses friendly and professional tone | D17: =IF(C17="Yes",1,0) -> 0
B18: Provides a warm and personalized welcome | D18: =IF(C18="Yes",1,0) -> 0
B19: Introduces self by name and role | D19: =IF(C19="Yes",1,0) -> 0
B20: Demonstrates cultural sensitivity | D20: =IF(C20="Yes",1,0) -> 0
B21: Name / Surname | D21: =IF(C21="Yes",1,0) -> 0
B22: Professional Appearance
B23: Follows dress code | D23: =IF(C23="Yes",1,0) -> 0
B24: Maintains neat grooming | D24: =IF(C24="Yes",1,0) -> 0
B25: Wears visible name badge (If not brand required mark as "YES" even if not being worn) | D25: =IF(C25="Yes",1,0) -> 0
B26: Environment Set Up
B27: Showroom is clean and organized | D27: =IF(C27="Yes",1,0) -> 0
B28: Desk is clean, organized and lacks clutter | D28: =IF(C28="Yes",1,0) -> 0
B29: Sales materials are readily available | D29: =IF(C29="Yes",1,0) -> 0
B30: Offers comfort (e.g., water, seating) | D30: =IF(C30="Yes",1,0) -> 0
B31: Communication
B32: Clear voice & tone | D32: =IF(C32="Yes",1,0) -> 0
B33: Enthusiastic and positive energy | D33: =IF(C33="Yes",1,0) -> 0
B34: Confidence | D34: =IF(C34="Yes",1,0) -> 0
B35: Show understanding and empathy | D35: =IF(C35="Yes",1,0) -> 0
B36: Questioning techniques | D36: =IF(C36="Yes",1,0) -> 0
B37: Building rapport and relationship | D37: =IF(C37="Yes",1,0) -> 0
B38: Demonstrate active listening skills | D38: =IF(C38="Yes",1,0) -> 0
B39: Always using the customer name / title | D39: =IF(C39="Yes",1,0) -> 0
B40: Appropriate Body Language | D40: =IF(C40="Yes",1,0) -> 0
B41: Progress through the Sales Process
B42: Smooth transition to a Sales Executive | D42: =IF(C42="Yes",1,0) -> 0
...

Sheet Handover Specialist 1
A1: SKILLS EVALUATION ASSESSMENT
A3: Date
A4: Brand
A5: Dealership
A6: Position
A7: Name | B7: HOS 1
A8: Start Date
A9: Assessor
B11: TASK 1
B12: MEET & GREET | C12: Y/N | G12: Score | H12: Pass | I12: Fail | J12: Max
B13: Initial Engagement | F13: MEET & GREET | G13: =D44 -> 0 | H13: 0.8 | I13: 0.6 | J13: 1
B14: Approaches customer promptly | D14: =IF(C14="Yes",1,0) -> 0 | F14: DELIVERY & FOLLOW UP | G14: =D72 -> 0 | H14: 0.8 | I14: 0.6 | J14: 1
B15: Thank Customer for their interest in the brand | D15: =IF(C15="Yes",1,0) -> 0 | F15: BRAND SPECIFIC REQUIREMENTS | G15: =D85 -> 0 | H15: 0.8 | I15: 0.6 | J15: 1
B16: Displays positive body language | D16: =IF(C16="Yes",1,0) -> 0 | F16: TOTAL SCORE | G16: =AVERAGE(G13:G15) -> 0 | H16: 0.8 | I16: 0.6 | J16: 1
B17: Uses friendly and professional tone | D17: =IF(C17="Yes",1,0) -> 0
B18: Provides a warm and personalized welcome | D18: =IF(C18="Yes",1,0) -> 0
B19: Introduces self by name and role | D19: =IF(C19="Yes",1,0) -> 0
B20: Demonstrates cultural sensitivity | D20: =IF(C20="Yes",1,0) -> 0
B21: Name / Surname | D21: =IF(C21="Yes",1,0) -> 0
B22: Professional Appearance
B23: Follows dress code | D23: =IF(C23="Yes",1,0) -> 0
B24: Maintains neat grooming | D24: =IF(C24="Yes",1,0) -> 0
B25: Wears visible name badge (If not brand required mark as "YES" even if not being worn) | D25: =IF(C25="Yes",1,0) -> 0
B26: Environment Set Up
B27: Showroom is clean and organized | D27: =IF(C27="Yes",1,0) -> 0
B28: Desk is clean, organized and lacks clutter | D28: =IF(C28="Yes",1,0) -> 0
B29: Sales materials are readily available | D29: =IF(C29="Yes",1,0) -> 0
B30: Offers comfort (e.g., water, seating) | D30: =IF(C30="Yes",1,0) -> 0
B31: Communication
B32: Clear voice & tone | D32: =IF(C32="Yes",1,0) -> 0
B33: Enthusiastic and positive energy | D33: =IF(C33="Yes",1,0) -> 0
B34: Confidence | D34: =IF(C34="Yes",1,0) -> 0
B35: Show understanding and empathy | D35: =IF(C35="Yes",1,0) -> 0
B36: Questioning techniques | D36: =IF(C36="Yes",1,0) -> 0
B37: Building rapport and relationship | D37: =IF(C37="Yes",1,0) -> 0
B38: Demonstrate active listening skills | D38: =IF(C38="Yes",1,0) -> 0
B39: Always using the customer name / title | D39: =IF(C39="Yes",1,0) -> 0
B40: Appropriate Body Language | D40: =IF(C40="Yes",1,0) -> 0
B41: Progress through the Sales Process
B42: Smooth transition into the Qualification stage | D42: =IF(C42="Yes",1,0) -> 0
...

Sheet Handover Specialist 2
A1: SKILLS EVALUATION ASSESSMENT
A3: Date
A4: Brand
A5: Dealership
A6: Position
A7: Name | B7: HOS 2
A8: Start Date
A9: Assessor
B11: TASK 1
B12: MEET & GREET | C12: Y/N | G12: Score | H12: Pass | I12: Fail | J12: Max
B13: Initial Engagement | F13: MEET & GREET | G13: =D44 -> 0 | H13: 0.8 | I13: 0.6 | J13: 1
B14: Approaches customer promptly | D14: =IF(C14="Yes",1,0) -> 0 | F14: DELIVERY & FOLLOW UP | G14: =D72 -> 0 | H14: 0.8 | I14: 0.6 | J14: 1
B15: Thank Customer for their interest in the brand | D15: =IF(C15="Yes",1,0) -> 0 | F15: BRAND SPECIFIC REQUIREMENTS | G15: =D85 -> 0 | H15: 0.8 | I15: 0.6 | J15: 1
B16: Displays positive body language | D16: =IF(C16="Yes",1,0) -> 0 | F16: TOTAL SCORE | G16: =AVERAGE(G13:G15) -> 0 | H16: 0.8 | I16: 0.6 | J16: 1
B17: Uses friendly and professional tone | D17: =IF(C17="Yes",1,0) -> 0
B18: Provides a warm and personalized welcome | D18: =IF(C18="Yes",1,0) -> 0
B19: Introduces self by name and role | D19: =IF(C19="Yes",1,0) -> 0
B20: Demonstrates cultural sensitivity | D20: =IF(C20="Yes",1,0) -> 0
B21: Name / Surname | D21: =IF(C21="Yes",1,0) -> 0
B22: Professional Appearance
B23: Follows dress code | D23: =IF(C23="Yes",1,0) -> 0
B24: Maintains neat grooming | D24: =IF(C24="Yes",1,0) -> 0
B25: Wears visible name badge (If not brand required mark as "YES" even if not being worn) | D25: =IF(C25="Yes",1,0) -> 0
B26: Environment Set Up
B27: Showroom is clean and organized | D27: =IF(C27="Yes",1,0) -> 0
B28: Desk is clean, organized and lacks clutter | D28: =IF(C28="Yes",1,0) -> 0
B29: Sales materials are readily available | D29: =IF(C29="Yes",1,0) -> 0
B30: Offers comfort (e.g., water, seating) | D30: =IF(C30="Yes",1,0) -> 0
B31: Communication
B32: Clear voice & tone | D32: =IF(C32="Yes",1,0) -> 0
B33: Enthusiastic and positive energy | D33: =IF(C33="Yes",1,0) -> 0
B34: Confidence | D34: =IF(C34="Yes",1,0) -> 0
B35: Show understanding and empathy | D35: =IF(C35="Yes",1,0) -> 0
B36: Questioning techniques | D36: =IF(C36="Yes",1,0) -> 0
B37: Building rapport and relationship | D37: =IF(C37="Yes",1,0) -> 0
B38: Demonstrate active listening skills | D38: =IF(C38="Yes",1,0) -> 0
B39: Always using the customer name / title | D39: =IF(C39="Yes",1,0) -> 0
B40: Appropriate Body Language | D40: =IF(C40="Yes",1,0) -> 0
B41: Progress through the Sales Process
B42: Smooth transition into the Qualification stage | D42: =IF(C42="Yes",1,0) -> 0
...

Sheet Handover Specialist 3
A1: SKILLS EVALUATION ASSESSMENT
A3: Date
A4: Brand
A5: Dealership
A6: Position
A7: Name | B7: HOS 3
A8: Start Date
A9: Assessor
B11: TASK 1
B12: MEET & GREET | C12: Y/N | G12: Score | H12: Pass | I12: Fail | J12: Max
B13: Initial Engagement | F13: MEET & GREET | G13: =D44 -> 0 | H13: 0.8 | I13: 0.6 | J13: 1
B14: Approaches customer promptly | D14: =IF(C14="Yes",1,0) -> 0 | F14: DELIVERY & FOLLOW UP | G14: =D72 -> 0 | H14: 0.8 | I14: 0.6 | J14: 1
B15: Thank Customer for their interest in the brand | D15: =IF(C15="Yes",1,0) -> 0 | F15: BRAND SPECIFIC REQUIREMENTS | G15: =D85 -> 0 | H15: 0.8 | I15: 0.6 | J15: 1
B16: Displays positive body language | D16: =IF(C16="Yes",1,0) -> 0 | F16: TOTAL SCORE | G16: =AVERAGE(G13:G15) -> 0 | H16: 0.8 | I16: 0.6 | J16: 1
B17: Uses friendly and professional tone | D17: =IF(C17="Yes",1,0) -> 0
B18: Provides a warm and personalized welcome | D18: =IF(C18="Yes",1,0) -> 0
B19: Introduces self by name and role | D19: =IF(C19="Yes",1,0) -> 0
B20: Demonstrates cultural sensitivity | D20: =IF(C20="Yes",1,0) -> 0
B21: Name / Surname | D21: =IF(C21="Yes",1,0) -> 0
B22: Professional Appearance
B23: Follows dress code | D23: =IF(C23="Yes",1,0) -> 0
B24: Maintains neat grooming | D24: =IF(C24="Yes",1,0) -> 0
B25: Wears visible name badge (If not brand required mark as "YES" even if not being worn) | D25: =IF(C25="Yes",1,0) -> 0
B26: Environment Set Up
B27: Showroom is clean and organized | D27: =IF(C27="Yes",1,0) -> 0
B28: Desk is clean, organized and lacks clutter | D28: =IF(C28="Yes",1,0) -> 0
B29: Sales materials are readily available | D29: =IF(C29="Yes",1,0) -> 0
B30: Offers comfort (e.g., water, seating) | D30: =IF(C30="Yes",1,0) -> 0
B31: Communication
B32: Clear voice & tone | D32: =IF(C32="Yes",1,0) -> 0
B33: Enthusiastic and positive energy | D33: =IF(C33="Yes",1,0) -> 0
B34: Confidence | D34: =IF(C34="Yes",1,0) -> 0
B35: Show understanding and empathy | D35: =IF(C35="Yes",1,0) -> 0
B36: Questioning techniques | D36: =IF(C36="Yes",1,0) -> 0
B37: Building rapport and relationship | D37: =IF(C37="Yes",1,0) -> 0
B38: Demonstrate active listening skills | D38: =IF(C38="Yes",1,0) -> 0
B39: Always using the customer name / title | D39: =IF(C39="Yes",1,0) -> 0
B40: Appropriate Body Language | D40: =IF(C40="Yes",1,0) -> 0
B41: Progress through the Sales Process
B42: Smooth transition into the Qualification stage | D42: =IF(C42="Yes",1,0) -> 0
...
